Welcome
Traceback (most recent call last):
  File "testApi.py", line 17, in <module>
    print "Welcome", client.get('/me')['firstname']
  File "/home/maidara/cloud/src/ovh/ovh/client.py", line 245, in get
    return self.call('GET', _target, None, _need_auth)
  File "/home/maidara/cloud/src/ovh/ovh/client.py", line 342, in call
    raise APIError(json_result.get('message'))
ovh.exceptions.APIError: This credential is not valid

